Workbook

Sheet ac
A1: Centro | B1: subCentro | C1: Código | D1: Cédula | E1: Cargo | F1: Nombre | G1: Credencial | H1: Empresa
A2: PRODUCCION 1 | B2: PRODUCCION OBRERO | C2: 27134 | D2: 0943442822 | E2: SERV GNRLES PRODUCCION | F2: ABAD CARRASCO JORDY RODOLFO | G2: 137653 | H2: SONGA
A3: PRODUCCION 1 | B3: PRODUCCION OBRERO | C3: 22526 | D3: 0923879274 | E3: SERV GNRLES PRODUCCION | F3: ABAD VILLAMAR WASHINGTHON WALTER | G3: 137604 | H3: SONGA
A4: CONTROL DE CALIDAD | B4: LAB FISICO QUIMICO | C4: 23252 | D4: 1716240591 | E4: JEFE DE LABORATORIO | F4: ABADIANO RIVERA GABRIELA FERNANDA | G4: 140567 | H4: SONGA
A5: PRODUCCION 1 | B5: PRODUCCION DPTO | C5: 27935 | D5: 0603726027 | E5: JEFE DE PLANTA | F5: ABARCA PARCO WILMER GUILLERMO | G5: 140445 | H5: SONGA
A6: PROD. RECEPCION SONGA 2 VA | B6: PROD.RECEPCION SONGA 2 VA | C6: 21389 | D6: 0957610041 | E6: SERV GNRLES PRODUCCION | F6: ABARCA PIN JOHNNY STEVEN | G6: 138383 | H6: SONGA
A7: LAVANDERIA | B7: LAVANDERIA | C7: 18524 | D7: 0951669589 | E7: SERV GNRLES PRODUCCION | F7: ACHILIE NAZARENO GELLER STEVEN | G7: 140335 | H7: SONGA
A8: PRODUCCION BRINE | B8: PRODUCCION BRINE | C8: 26860 | D8: 0959223900 | E8: SERV GNRLES PRODUCCION | F8: ACOSTA FLOR KEVIN JOSUE | G8: 136829 | H8: SONGA
A9: TALENTO HUMANO | B9: RECURSOS HUMANOS | C9: 26643 | D9: 0923886444 | E9: ANALISTA DE SELECC. Y DESA. | F9: ACOSTA FLOR LAURA GIANELLA | G9: 136112 | H9: SONGA
A10: PRODUCCION 1 | B10: PRODUCCION OBRERO | C10: 25970 | D10: 0956761076 | E10: SERV GNRLES PRODUCCION | F10: ACOSTA JAIME MARLON RAUL | G10: 135421 | H10: SONGA
A11: CONTROL DE CALIDAD EXTERIORES | B11: CONTROL DE CALIDAD EXTERIORES | C11: 19706 | D11: 0944223213 | E11: AYUDANTE ORGANOLEPTICO | F11: ACOSTA LOPEZ FREDD ABRAHAM | G11: 124165 | H11: SONGA
A12: PRODUCCION BRINE | B12: PRODUCCION BRINE | C12: 26774 | D12: 0926690934 | E12: SERV GNRLES PRODUCCION | F12: ACOSTA PINCAY LUIS ENRIQUE | G12: 136558 | H12: SONGA
... A3510: SEAFOOD | B3510: SEAFOOD | C3510: 50 | D3510: 2300580921 | E3510: ASISTENTE COMERCIAL | F3510: SOTO ESPINOSA TATIANA ELIZABETH | G3510: 2300580921 | H3510: SEAFOOD

Sheet Hoja1
A2: CEDULA | B2: Empleado | C2: Carga | D2: EMPRESA
A3: 923879274 | B3: ABAD VILLAMAR WASHINGTHON WALTER | C3: 1 | D3: SONGA
A4: 926690934 | B4: ACOSTA PINCAY LUIS ENRIQUE | C4: 4 | D4: SONGA
A5: 919844548 | B5: ACUÑA CHONG CRISTINA JOHANNA | C5: 1 | D5: SONGA
A6: 951891746 | B6: ADRIANO MACAS JENNIFER ALEXANDRA | C6: 1 | D6: SONGA
A7: 805029998 | B7: AGRACE CASTILLO YARITZA YULIANA | C7: 1 | D7: SONGA
A8: 914231733 | B8: AGUAYO COQUE CARLOS RAMON | C8: 1 | D8: SEGULASA
A9: 918204843 | B9: AGUAYO ZAMBRANO DANIEL STALYN | C9: 1 | D9: SONGA
A10: 932083850 | B10: AGUILAR CRUZ ANTHONY MICHAEL | C10: 1 | D10: SONGA
A11: 943440099 | B11: AGUILAR PALACIOS LEONARDO MOISES | C11: 1 | D11: SONGA
A12: 931573026 | B12: AGUILERA FLORES JOSELYN MAYIYA | C12: 1 | D12: SONGA
A13: 925032989 | B13: ALARCON ALARCON ANDRES ALEJANDRO | C13: 1 | D13: SONGA
A14: 953052628 | B14: ALARCON BAUTISTA MAYERLY NIKOOL | C14: 1 | D14: SONGA
... A1067: 929264448 | B1067: QUINTERO ANGULO JOHANNA ELIZABETH | C1067: 2 | D1067: SONGA
A1068: AU773839 | B1068: QUINTERO BERMUDEZ JONATHAN | C1068: 1 | D1068: SONGA
A1069: 940298250 | B1069: QUINTERO CAICEDO LUIGI JEFFERSON | C1069: 1 | D1069: SONGA
A1070: 928908052 | B1070: QUINTERO CAICEDO WENDY EUGENIA | C1070: 1 | D1070: SONGA
A1071: 958276024 | B1071: QUINTERO CAÑIZARES BEATRIZ MILENA | C1071: 1 | D1071: SONGA
A1072: 926662255 | B1072: QUINTERO LOPEZ MARIA HERMINIA | C1072: 1 | D1072: SONGA
A1073: 950190009 | B1073: QUINTERO PRECIADO ALICIA CELINA | C1073: 1 | D1073: SONGA
A1074: 940944929 | B1074: QUINTERO QUINTERO DEISI ALEXANDRA | C1074: 5 | D1074: SONGA
A1075: 920509205 | B1075: QUINTO GARBOA KLEBER SANTIAGO | C1075: 1 | D1075: SONGA
A1076: 921270427 | B1076: QUINTO LOPEZ CARLOS FERNANDO | C1076: 1 | D1076: SONGA
A1077: 941689556 | B1077: QUINTO SEA OMAIRA FABIOLA | C1077: 1 | D1077: SONGA
A1078: 921135737 | B1078: QUINTUÑA PEREZ WILPER VICENTE | C1078: 2 | D1078: SONGA
A1079: 941255903 | B1079: QUIÑONEZ ANGULO JENIFFER CAROLINA | C1079: 1 | D1079: SONGA
A1080: 955975727 | B1080: QUIÑONEZ ANGULO RUTH MAYTE | C1080: 3 | D1080: SONGA
... A1466: 951528447 | B1466: ZUÑIGA CAÑARTE LEONARDO ANTONIO | C1466: 3 | D1466: SEGULASA

Sheet Hoja2
A1: Centro | B1: Credencial | C1: Cédula | D1: Cargo | E1: Nombre | F1: Grupo
A2: PRODUCCION 1 | B2: 165121 | C2: 0957220304 | D2: SERV GNRLES PRODUCCION | E2: ABAD HOLGUIN DILAN ALEXANDER | F2: GRUPO # 14
A3: PROD.LIMPIEZA INT.SONGA 2 VA | B3: 164757 | C3: 0923223226 | D3: SERV GNRLES PRODUCCION | E3: ABAD MORAN JOFFRE EDUARDO | F3: PROD.LIMP.INTERIOR SONGA 2
A4: PRODUCCION 1 | B4: 165270 | C4: 0923879274 | D4: SERV GNRLES PRODUCCION | E4: ABAD VILLAMAR WASHINGTHON WALTER | F4: GRUPO # 18
A5: CONTROL DE CALIDAD | B5: 161037 | C5: 1716240591 | D5: JEFE DE LABORATORIO | E5: ABADIANO RIVERA GABRIELA FERNANDA | F5: CONTROL DE CALIDAD
A6: PROD. RECEPCION SONGA 2 VA | B6: 138383 | C6: 0957610041 | D6: SERV GNRLES PRODUCCION | E6: ABARCA PIN JOHNNY STEVEN | F6: RECEPCION S2 G4
A7: PRODUCCION 1 | B7: 165229 | C7: 0931862031 | D7: SERV GNRLES PRODUCCION | E7: ABATTE CARPIO RAUL ALFREDO | F7: GRUPO # 12
A8: PELADO SONGA 2 VA | B8: 165561 | C8: 0958959827 | D8: SERV GNRLES PRODUCCION | E8: ACENCIO GONZALEZ SARA NALLELY | F8: GRUPO 7 VAGS2
A9: LAVANDERIA | B9: 140335 | C9: 0951669589 | D9: SERV GNRLES PRODUCCION | E9: ACHILIE NAZARENO GELLER STEVEN | F9: LAVANDERIA SONGA 1
A10: PELADO SONGA 2 VA | B10: 163639 | C10: 0941166266 | D10: SERV GNRLES PRODUCCION | E10: ACOSTA CAJAS MARGARETH KATIUSKA | F10: GRUPO 7 VAGS2
A11: PELADO SONGA 2 VA | B11: 161895 | C11: 0941649360 | D11: SERV GNRLES PRODUCCION | E11: ACOSTA CHOEZ ARIEL ALFREDO | F11: PELADO AUTOMATICO G4
A12: PRODUCCION BRINE | B12: 163026 | C12: 0959223900 | D12: SERV GNRLES PRODUCCION | E12: ACOSTA FLOR KEVIN JOSUE | F12: BRINE # 3
A13: TALENTO HUMANO | B13: 163345 | C13: 0923886444 | D13: ANALISTA DE SELECC. Y DESA. | E13: ACOSTA FLOR LAURA GIANELLA | F13: TALENTO HUMANO
... A4044: PROD. DESCABEZADO SONGA 2 VA | B4044: 162515 | C4044: 0925072324 | D4044: SERV GNRLES PRODUCCION | E4044: ZUÑIGA TORRES ZULLY PRISCILLA | F4044: ESCUELA DE DESCABEZADO

Sheet Base empleados 2025
A1: COD | B1: CEDULA | C1: APELLIDOS Y NOMBRES | D1: CEDULA | E1: AREA | F1: COD | G1: EMPRESA | H1: Grupo | I1: Turno
A2: 165121 | B2: 957220304 | C2: ABAD HOLGUIN DILAN ALEXANDER | D2: 957220304 | E2: PRODUCCION 1 | F2: 165121 | G2: SONGA
A3: 164757 | B3: 923223226 | C3: ABAD MORAN JOFFRE EDUARDO | D3: 923223226 | E3: PROD.LIMPIEZA INT.SONGA 2 VA | F3: 164757 | G3: SONGA
A4: 165270 | B4: 923879274 | C4: ABAD VILLAMAR WASHINGTHON WALTER | D4: 923879274 | E4: PRODUCCION 1 | F4: 165270 | G4: SONGA
A5: 161037 | B5: 1716240591 | C5: ABADIANO RIVERA GABRIELA FERNANDA | D5: 1716240591 | E5: CONTROL DE CALIDAD | F5: 161037 | G5: SONGA
A6: 138383 | B6: 957610041 | C6: ABARCA PIN JOHNNY STEVEN | D6: 957610041 | E6: PROD. RECEPCION SONGA 2 VA | F6: 138383 | G6: SONGA
A7: 165229 | B7: 931862031 | C7: ABATTE CARPIO RAUL ALFREDO | D7: 931862031 | E7: PRODUCCION 1 | F7: 165229 | G7: SONGA
A8: 165561 | B8: 958959827 | C8: ACENCIO GONZALEZ SARA NALLELY | D8: 958959827 | E8: PELADO SONGA 2 VA | F8: 165561 | G8: SONGA
A9: 140335 | B9: 951669589 | C9: ACHILIE NAZARENO GELLER STEVEN | D9: 951669589 | E9: LAVANDERIA | F9: 140335 | G9: SONGA
A10: 163639 | B10: 941166266 | C10: ACOSTA CAJAS MARGARETH KATIUSKA | D10: 941166266 | E10: PELADO SONGA 2 VA | F10: 163639 | G10: SONGA
A11: 161895 | B11: 941649360 | C11: ACOSTA CHOEZ ARIEL ALFREDO | D11: 941649360 | E11: PELADO SONGA 2 VA | F11: 161895 | G11: SONGA
A12: 163026 | B12: 959223900 | C12: ACOSTA FLOR KEVIN JOSUE | D12: 959223900 | E12: PRODUCCION BRINE | F12: 163026 | G12: SONGA
A13: 163345 | B13: 923886444 | C13: ACOSTA FLOR LAURA GIANELLA | D13: 923886444 | E13: TALENTO HUMANO | F13: 163345 | G13: SONGA
... A3370: 164198 | B3370: 943928721 | C3370: SANJINEZ FRANCO NAOMI ALEXANDRA | D3370: 943928721 | E3370: PROD. DESCABEZADO SONGA 2 VA | F3370: 164198 | G3370: SONGA
A3371: 160708 | B3371: AY749178 | C3371: SANTAFE BAUTISTA ANDRES DARIO | D3371: AY749178 | E3371: PRODUCCIÓN SONGA 2 VA | F3371: 160708 | G3371: SONGA
A3372: 165193 | B3372: 959441338 | C3372: SANTANA CAICEDO STIVEEN JAVIER | D3372: 959441338 | E3372: CAMARA DE ALMACENAMIENTO 1 | F3372: 165193 | G3372: SONGA
A3373: 142911 | B3373: 931086318 | C3373: SANTANA ESPINOZA OSCAR JOEL | D3373: 931086318 | E3373: PELADO SONGA 2 VA | F3373: 142911 | G3373: SONGA
A3374: 163523 | B3374: 927094144 | C3374: SANTANA FLORES JONATHAN DARWIN | D3374: 927094144 | E3374: ETIQUETAS | F3374: 163523 | G3374: SONGA
A3375: 145838 | B3375: 914391693 | C3375: SANTANA LOPEZ MARIANITA DE LOURDES | D3375: 914391693 | E3375: PELADO SONGA 2 VA | F3375: 145838 | G3375: SONGA
A3376: 165402 | B3376: 956031579 | C3376: SANTANA MERCHAN BRITHNEY CAMILA | D3376: 956031579 | E3376: PELADO SONGA 2 VA | F3376: 165402 | G3376: SONGA
A3377: 142372 | B3377: 952894079 | C3377: SANTANA SILVA JONATHAN MOISES | D3377: 952894079 | E3377: PRODUCCION 1 | F3377: 142372 | G3377: SONGA
A3378: 162709 | B3378: 953541240 | C3378: SANTANA VERA KEVIN ALBERTO | D3378: 953541240 | E3378: PRODUCCION 1 | F3378: 162709 | G3378: SONGA
A3379: 140911 | B3379: 958409534 | C3379: SANTANA ZAPATA ANTHONY JOSUE | D3379: 958409534 | E3379: EMBARQUE | F3379: 140911 | G3379: SONGA
A3380: 141344 | B3380: 924601537 | C3380: SANTILLAN SALINAS MARTHA CECILIA | D3380: 924601537 | E3380: PRODUCCION 1 | F3380: 141344 | G3380: SONGA
A3381: 139683 | B3381: 914967245 | C3381: SANTOS FALCONES TANYA ANALLELY | D3381: 914967245 | E3381: TALENTO HUMANO | F3381: 139683 | G3381: SONGA
A3382: 141489 | B3382: 950937433 | C3382: SANTOS MERA ESTALIN JOHN | D3382: 950937433 | E3382: IQF SONGA 1 | F3382: 141489 | G3382: SONGA
A3383: 142023 | B3383: 1205237322 | C3383: SANTOS MUGUERZA OSCAR HUMBERTO | D3383: 1205237322 | E3383: LOGISTICA Y TRANSPORTES | F3383: 142023 | G3383: SONGA
... A3746: 163178 | B3746: 910930130 | C3746: VARGAS GONZALEZ WALTHER GIOVANNI | D3746: 910930130 | E3746: PROD. DESCABEZADO SONGA 2 VA | F3746: 163178 | G3746: SONGA
A3747: 163017 | B3747: AT773028 | C3747: VARGAS GRISALES JUAN PABLO | D3747: AT773028 | E3747: CONTROL DE CALIDAD | F3747: 163017 | G3747: SONGA
A3748: 162472 | B3748: 928117118 | C3748: VARGAS GUALE DAVIS SANTOS | D3748: 928117118 | E3748: LIQUIDACION DE PROD.SONGA 2 VA | F3748: 162472 | G3748: SONGA
A3749: 140230 | B3749: 912004827 | C3749: VARGAS JUANAZO JULIA MARIA | D3749: 912004827 | E3749: PRODUCCION 1 | F3749: 140230 | G3749: SONGA
A3750: 161055 | B3750: 953734761 | C3750: VARGAS MARTINEZ ADRIAN STEVEN | D3750: 953734761 | E3750: PRODUCCION CAJAS | F3750: 161055 | G3750: SONGA
A3751: 140055 | B3751: 923052534 | C3751: VARGAS PAREDES EDGAR ADRIAN | D3751: 923052534 | E3751: MANTENIMIENTO REFRIGERACION | F3751: 140055 | G3751: SONGA
A3752: 163033 | B3752: 195518092 | C3752: VARGAS PARRA FRANCISCO JAVIER | D3752: 195518092 | E3752: PRODUCCIÓN SONGA 2 VA | F3752: 163033 | G3752: SONGA
A3753: 161441 | B3753: 922631841 | C3753: VARGAS PEÑALOZA MAYRA CAROLINA | D3753: 922631841 | E3753: PROD. DESCABEZADO SONGA 2 VA | F3753: 161441 | G3753: SONGA
A3754: 161766 | B3754: 942779232 | C3754: VARGAS UBE KAREN LISSETH | D3754: 942779232 | E3754: IQF SONGA 1 | F3754: 161766 | G3754: SONGA
A3755: 161111 | B3755: 920693207 | C3755: VARGAS VALDEZ FREDDY MANUEL | D3755: 920693207 | E3755: MANTENIMIENTO MEC.CLASIFICADOR | F3755: 161111 | G3755: SONGA
A3756: 161040 | B3756: 929249175 | C3756: VASQUEZ ACOSTA DANIEL ARMANDO | D3756: 929249175 | E3756: PROD.LIMPIEZA INT.SONGA 2 VA | F3756: 161040 | G3756: SONGA
A3757: 163805 | B3757: 926172636 | C3757: VASQUEZ ANDRADE MARIO JAVIER | D3757: 926172636 | E3757: PROD.LIMPIEZA INT.SONGA 2 VA | F3757: 163805 | G3757: SONGA
A3758: 165278 | B3758: 957057128 | C3758: VASQUEZ APOLINARIO MARIA GENESIS | D3758: 957057128 | E3758: PRODUCCION 1 | F3758: 165278 | G3758: SONGA
...

Sheet PLT-D
B1: SOCIEDAD NACIONAL DE GALAPAGOS C.A.
B2: REGISTRO ASISTENCIA OLIMPIADAS 2025
C3: FECHA: | D3: =TODAY() -> 46259
A4: LECTOR | B4: No. | C4: COD | D4: APELLIDOS Y NOMBRES | E4: CEDULAS | F4: AREA | G4: EMPRESA | J4: Cargas
B5: 1 | C5: =IF(A5="","",IF(ISERROR(VLOOKUP(A5,'Base empleados 2025'!$A:$F,6,FALSE)),VLOOKUP(A5,'Base empleados 2025'!$B:$F,5,FALSE),VLOOKUP(A5,'Base empleados 2025'!$A:$F,6,FALSE))) | D5: =IF(A5="","",IF(ISERROR(VLOOKUP(A5,'Base empleados 2025'!$A:$F,3,FALSE)),VLOOKUP(A5,'Base empleados 2025'!$B:$F,2,FALSE),VLOOKUP(A5,'Base empleados 2025'!$A:$F,3,FALSE))) | E5: =IF(A5="","",IF(ISERROR(VLOOKUP(A5,'Base empleados 2025'!$A:$F,4,FALSE)),VLOOKUP(A5,'Base empleados 2025'!$B:$F,3,FALSE),VLOOKUP(A5,'Base empleados 2025'!$A:$F,4,FALSE))) | F5: =IF(A5="","",IF(ISERROR(VLOOKUP(A5,'Base empleados 2025'!$A:$F,5,FALSE)),VLOOKUP(A5,'Base empleados 2025'!$B:$F,4,FALSE),VLOOKUP(A5,'Base empleados 2025'!$A:$F,5,FALSE))) | G5: =IF(D5="","",VLOOKUP(D5,'Base empleados 2025'!C:G,5,FALSE)) | H5: =IF(ISERROR(VLOOKUP(E5,$E$4:F4,2,FALSE)),"","REPETIDO") | J5: =IF(E5="","",VLOOKUP(E5,'Base empleados 2025'!B:G,6,FALSE)) | K5: =IF(A5="","",VLOOKUP(A5,'Base empleados 2025'!B:H,6,0)) | L5: =IF(A5="","",VLOOKUP(A5,'Base empleados 2025'!A:I,9,0))
B6: =+IF(C6="","",B5+1) | C6: =IF(A6="","",IF(ISERROR(VLOOKUP(A6,'Base empleados 2025'!$A:$F,6,FALSE)),VLOOKUP(A6,'Base empleados 2025'!$B:$F,5,FALSE),VLOOKUP(A6,'Base empleados 2025'!$A:$F,6,FALSE))) | D6: =IF(A6="","",IF(ISERROR(VLOOKUP(A6,'Base empleados 2025'!$A:$F,3,FALSE)),VLOOKUP(A6,'Base empleados 2025'!$B:$F,2,FALSE),VLOOKUP(A6,'Base empleados 2025'!$A:$F,3,FALSE))) | E6: =IF(A6="","",IF(ISERROR(VLOOKUP(A6,'Base empleados 2025'!$A:$F,4,FALSE)),VLOOKUP(A6,'Base empleados 2025'!$B:$F,3,FALSE),VLOOKUP(A6,'Base empleados 2025'!$A:$F,4,FALSE))) | F6: =IF(A6="","",IF(ISERROR(VLOOKUP(A6,'Base empleados 2025'!$A:$F,5,FALSE)),VLOOKUP(A6,'Base empleados 2025'!$B:$F,4,FALSE),VLOOKUP(A6,'Base empleados 2025'!$A:$F,5,FALSE))) | G6: =IF(D6="","",VLOOKUP(D6,'Base empleados 2025'!C:G,5,FALSE)) | H6: =IF(ISERROR(VLOOKUP(E6,$E$4:F5,2,FALSE)),"","REPETIDO") -> REPETIDO | J6: =IF(E6="","",VLOOKUP(E6,'Base empleados 2025'!B:G,6,FALSE)) | K6: =IF(A6="","",VLOOKUP(A6,'Base empleados 2025'!A:H,8,0)) | L6: =IF(A6="","",VLOOKUP(A6,'Base empleados 2025'!A:I,9,0))
B7: =+IF(C7="","",B6+1) | C7: =IF(A7="","",IF(ISERROR(VLOOKUP(A7,'Base empleados 2025'!$A:$F,6,FALSE)),VLOOKUP(A7,'Base empleados 2025'!$B:$F,5,FALSE),VLOOKUP(A7,'Base empleados 2025'!$A:$F,6,FALSE))) | D7: =IF(A7="","",IF(ISERROR(VLOOKUP(A7,'Base empleados 2025'!$A:$F,3,FALSE)),VLOOKUP(A7,'Base empleados 2025'!$B:$F,2,FALSE),VLOOKUP(A7,'Base empleados 2025'!$A:$F,3,FALSE))) | E7: =IF(A7="","",IF(ISERROR(VLOOKUP(A7,'Base empleados 2025'!$A:$F,4,FALSE)),VLOOKUP(A7,'Base empleados 2025'!$B:$F,3,FALSE),VLOOKUP(A7,'Base empleados 2025'!$A:$F,4,FALSE))) | F7: =IF(A7="","",IF(ISERROR(VLOOKUP(A7,'Base empleados 2025'!$A:$F,5,FALSE)),VLOOKUP(A7,'Base empleados 2025'!$B:$F,4,FALSE),VLOOKUP(A7,'Base empleados 2025'!$A:$F,5,FALSE))) | G7: =IF(D7="","",VLOOKUP(D7,'Base empleados 2025'!C:G,5,FALSE)) | H7: =IF(ISERROR(VLOOKUP(E7,$E$4:F6,2,FALSE)),"","REPETIDO") -> REPETIDO | J7: =IF(E7="","",VLOOKUP(E7,'Base empleados 2025'!B:G,6,FALSE)) | K7: =IF(A7="","",VLOOKUP(A7,'Base empleados 2025'!A:H,8,0)) | L7: =IF(A7="","",VLOOKUP(A7,'Base empleados 2025'!A:I,9,0))
B8: =+IF(C8="","",B7+1) | C8: =IF(A8="","",IF(ISERROR(VLOOKUP(A8,'Base empleados 2025'!$A:$F,6,FALSE)),VLOOKUP(A8,'Base empleados 2025'!$B:$F,5,FALSE),VLOOKUP(A8,'Base empleados 2025'!$A:$F,6,FALSE))) | D8: =IF(A8="","",IF(ISERROR(VLOOKUP(A8,'Base empleados 2025'!$A:$F,3,FALSE)),VLOOKUP(A8,'Base empleados 2025'!$B:$F,2,FALSE),VLOOKUP(A8,'Base empleados 2025'!$A:$F,3,FALSE))) | E8: =IF(A8="","",IF(ISERROR(VLOOKUP(A8,'Base empleados 2025'!$A:$F,4,FALSE)),VLOOKUP(A8,'Base empleados 2025'!$B:$F,3,FALSE),VLOOKUP(A8,'Base empleados 2025'!$A:$F,4,FALSE))) | F8: =IF(A8="","",IF(ISERROR(VLOOKUP(A8,'Base empleados 2025'!$A:$F,5,FALSE)),VLOOKUP(A8,'Base empleados 2025'!$B:$F,4,FALSE),VLOOKUP(A8,'Base empleados 2025'!$A:$F,5,FALSE))) | G8: =IF(D8="","",VLOOKUP(D8,'Base empleados 2025'!C:G,5,FALSE)) | H8: =IF(ISERROR(VLOOKUP(E8,$E$4:F7,2,FALSE)),"","REPETIDO") -> REPETIDO | J8: =IF(E8="","",VLOOKUP(E8,'Base empleados 2025'!B:G,6,FALSE)) | K8: =IF(A8="","",VLOOKUP(A8,'Base empleados 2025'!A:H,8,0)) | L8: =IF(A8="","",VLOOKUP(A8,'Base empleados 2025'!A:I,9,0))
B9: =+IF(C9="","",B8+1) | C9: =IF(A9="","",IF(ISERROR(VLOOKUP(A9,'Base empleados 2025'!$A:$F,6,FALSE)),VLOOKUP(A9,'Base empleados 2025'!$B:$F,5,FALSE),VLOOKUP(A9,'Base empleados 2025'!$A:$F,6,FALSE))) | D9: =IF(A9="","",IF(ISERROR(VLOOKUP(A9,'Base empleados 2025'!$A:$F,3,FALSE)),VLOOKUP(A9,'Base empleados 2025'!$B:$F,2,FALSE),VLOOKUP(A9,'Base empleados 2025'!$A:$F,3,FALSE))) | E9: =IF(A9="","",IF(ISERROR(VLOOKUP(A9,'Base empleados 2025'!$A:$F,4,FALSE)),VLOOKUP(A9,'Base empleados 2025'!$B:$F,3,FALSE),VLOOKUP(A9,'Base empleados 2025'!$A:$F,4,FALSE))) | F9: =IF(A9="","",IF(ISERROR(VLOOKUP(A9,'Base empleados 2025'!$A:$F,5,FALSE)),VLOOKUP(A9,'Base empleados 2025'!$B:$F,4,FALSE),VLOOKUP(A9,'Base empleados 2025'!$A:$F,5,FALSE))) | G9: =IF(D9="","",VLOOKUP(D9,'Base empleados 2025'!C:G,5,FALSE)) | H9: =IF(ISERROR(VLOOKUP(E9,$E$4:F8,2,FALSE)),"","REPETIDO") -> REPETIDO | J9: =IF(E9="","",VLOOKUP(E9,'Base empleados 2025'!B:G,6,FALSE)) | K9: =IF(A9="","",VLOOKUP(A9,'Base empleados 2025'!A:H,8,0)) | L9: =IF(A9="","",VLOOKUP(A9,'Base empleados 2025'!A:I,9,0))
B10: =+IF(C10="","",B9+1) | C10: =IF(A10="","",IF(ISERROR(VLOOKUP(A10,'Base empleados 2025'!$A:$F,6,FALSE)),VLOOKUP(A10,'Base empleados 2025'!$B:$F,5,FALSE),VLOOKUP(A10,'Base empleados 2025'!$A:$F,6,FALSE))) | D10: =IF(A10="","",IF(ISERROR(VLOOKUP(A10,'Base empleados 2025'!$A:$F,3,FALSE)),VLOOKUP(A10,'Base empleados 2025'!$B:$F,2,FALSE),VLOOKUP(A10,'Base empleados 2025'!$A:$F,3,FALSE))) | E10: =IF(A10="","",IF(ISERROR(VLOOKUP(A10,'Base empleados 2025'!$A:$F,4,FALSE)),VLOOKUP(A10,'Base empleados 2025'!$B:$F,3,FALSE),VLOOKUP(A10,'Base empleados 2025'!$A:$F,4,FALSE))) | F10: =IF(A10="","",IF(ISERROR(VLOOKUP(A10,'Base empleados 2025'!$A:$F,5,FALSE)),VLOOKUP(A10,'Base empleados 2025'!$B:$F,4,FALSE),VLOOKUP(A10,'Base empleados 2025'!$A:$F,5,FALSE))) | G10: =IF(D10="","",VLOOKUP(D10,'Base empleados 2025'!C:G,5,FALSE)) | H10: =IF(ISERROR(VLOOKUP(E10,$E$4:F9,2,FALSE)),"","REPETIDO") -> REPETIDO | J10: =IF(E10="","",VLOOKUP(E10,'Base empleados 2025'!B:G,6,FALSE)) | K10: =IF(A10="","",VLOOKUP(A10,'Base empleados 2025'!A:H,8,0)) | L10: =IF(A10="","",VLOOKUP(A10,'Base empleados 2025'!A:I,9,0))
B11: =+IF(C11="","",B10+1) | C11: =IF(A11="","",IF(ISERROR(VLOOKUP(A11,'Base empleados 2025'!$A:$F,6,FALSE)),VLOOKUP(A11,'Base empleados 2025'!$B:$F,5,FALSE),VLOOKUP(A11,'Base empleados 2025'!$A:$F,6,FALSE))) | D11: =IF(A11="","",IF(ISERROR(VLOOKUP(A11,'Base empleados 2025'!$A:$F,3,FALSE)),VLOOKUP(A11,'Base empleados 2025'!$B:$F,2,FALSE),VLOOKUP(A11,'Base empleados 2025'!$A:$F,3,FALSE))) | E11: =IF(A11="","",IF(ISERROR(VLOOKUP(A11,'Base empleados 2025'!$A:$F,4,FALSE)),VLOOKUP(A11,'Base empleados 2025'!$B:$F,3,FALSE),VLOOKUP(A11,'Base empleados 2025'!$A:$F,4,FALSE))) | F11: =IF(A11="","",IF(ISERROR(VLOOKUP(A11,'Base empleados 2025'!$A:$F,5,FALSE)),VLOOKUP(A11,'Base empleados 2025'!$B:$F,4,FALSE),VLOOKUP(A11,'Base empleados 2025'!$A:$F,5,FALSE))) | G11: =IF(D11="","",VLOOKUP(D11,'Base empleados 2025'!C:G,5,FALSE)) | H11: =IF(ISERROR(VLOOKUP(E11,$E$4:F10,2,FALSE)),"","REPETIDO") -> REPETIDO | J11: =IF(E11="","",VLOOKUP(E11,'Base empleados 2025'!B:G,6,FALSE)) | K11: =IF(A11="","",VLOOKUP(A11,'Base empleados 2025'!A:H,8,0)) | L11: =IF(A11="","",VLOOKUP(A11,'Base empleados 2025'!A:I,9,0))
B12: =+IF(C12="","",B11+1) | C12: =IF(A12="","",IF(ISERROR(VLOOKUP(A12,'Base empleados 2025'!$A:$F,6,FALSE)),VLOOKUP(A12,'Base empleados 2025'!$B:$F,5,FALSE),VLOOKUP(A12,'Base empleados 2025'!$A:$F,6,FALSE))) | D12: =IF(A12="","",IF(ISERROR(VLOOKUP(A12,'Base empleados 2025'!$A:$F,3,FALSE)),VLOOKUP(A12,'Base empleados 2025'!$B:$F,2,FALSE),VLOOKUP(A12,'Base empleados 2025'!$A:$F,3,FALSE))) | E12: =IF(A12="","",IF(ISERROR(VLOOKUP(A12,'Base empleados 2025'!$A:$F,4,FALSE)),VLOOKUP(A12,'Base empleados 2025'!$B:$F,3,FALSE),VLOOKUP(A12,'Base empleados 2025'!$A:$F,4,FALSE))) | F12: =IF(A12="","",IF(ISERROR(VLOOKUP(A12,'Base empleados 2025'!$A:$F,5,FALSE)),VLOOKUP(A12,'Base empleados 2025'!$B:$F,4,FALSE),VLOOKUP(A12,'Base empleados 2025'!$A:$F,5,FALSE))) | G12: =IF(D12="","",VLOOKUP(D12,'Base empleados 2025'!C:G,5,FALSE)) | H12: =IF(ISERROR(VLOOKUP(E12,$E$4:F11,2,FALSE)),"","REPETIDO") -> REPETIDO | J12: =IF(E12="","",VLOOKUP(E12,'Base empleados 2025'!B:G,6,FALSE)) | K12: =IF(A12="","",VLOOKUP(A12,'Base empleados 2025'!A:H,8,0)) | L12: =IF(A12="","",VLOOKUP(A12,'Base empleados 2025'!A:I,9,0))
B13: =+IF(C13="","",B12+1) | C13: =IF(A13="","",IF(ISERROR(VLOOKUP(A13,'Base empleados 2025'!$A:$F,6,FALSE)),VLOOKUP(A13,'Base empleados 2025'!$B:$F,5,FALSE),VLOOKUP(A13,'Base empleados 2025'!$A:$F,6,FALSE))) | D13: =IF(A13="","",IF(ISERROR(VLOOKUP(A13,'Base empleados 2025'!$A:$F,3,FALSE)),VLOOKUP(A13,'Base empleados 2025'!$B:$F,2,FALSE),VLOOKUP(A13,'Base empleados 2025'!$A:$F,3,FALSE))) | E13: =IF(A13="","",IF(ISERROR(VLOOKUP(A13,'Base empleados 2025'!$A:$F,4,FALSE)),VLOOKUP(A13,'Base empleados 2025'!$B:$F,3,FALSE),VLOOKUP(A13,'Base empleados 2025'!$A:$F,4,FALSE))) | F13: =IF(A13="","",IF(ISERROR(VLOOKUP(A13,'Base empleados 2025'!$A:$F,5,FALSE)),VLOOKUP(A13,'Base empleados 2025'!$B:$F,4,FALSE),VLOOKUP(A13,'Base empleados 2025'!$A:$F,5,FALSE))) | G13: =IF(D13="","",VLOOKUP(D13,'Base empleados 2025'!C:G,5,FALSE)) | H13: =IF(ISERROR(VLOOKUP(E13,$E$4:F12,2,FALSE)),"","REPETIDO") -> REPETIDO | J13: =IF(E13="","",VLOOKUP(E13,'Base empleados 2025'!B:G,6,FALSE)) | K13: =IF(A13="","",VLOOKUP(A13,'Base empleados 2025'!A:H,8,0)) | L13: =IF(A13="","",VLOOKUP(A13,'Base empleados 2025'!A:I,9,0))
B14: =+IF(C14="","",B13+1) | C14: =IF(A14="","",IF(ISERROR(VLOOKUP(A14,'Base empleados 2025'!$A:$F,6,FALSE)),VLOOKUP(A14,'Base empleados 2025'!$B:$F,5,FALSE),VLOOKUP(A14,'Base empleados 2025'!$A:$F,6,FALSE))) | D14: =IF(A14="","",IF(ISERROR(VLOOKUP(A14,'Base empleados 2025'!$A:$F,3,FALSE)),VLOOKUP(A14,'Base empleados 2025'!$B:$F,2,FALSE),VLOOKUP(A14,'Base empleados 2025'!$A:$F,3,FALSE))) | E14: =IF(A14="","",IF(ISERROR(VLOOKUP(A14,'Base empleados 2025'!$A:$F,4,FALSE)),VLOOKUP(A14,'Base empleados 2025'!$B:$F,3,FALSE),VLOOKUP(A14,'Base empleados 2025'!$A:$F,4,FALSE))) | F14: =IF(A14="","",IF(ISERROR(VLOOKUP(A14,'Base empleados 2025'!$A:$F,5,FALSE)),VLOOKUP(A14,'Base empleados 2025'!$B:$F,4,FALSE),VLOOKUP(A14,'Base empleados 2025'!$A:$F,5,FALSE))) | G14: =IF(D14="","",VLOOKUP(D14,'Base empleados 2025'!C:G,5,FALSE)) | H14: =IF(ISERROR(VLOOKUP(E14,$E$4:F13,2,FALSE)),"","REPETIDO") -> REPETIDO | J14: =IF(E14="","",VLOOKUP(E14,'Base empleados 2025'!B:G,6,FALSE)) | K14: =IF(A14="","",VLOOKUP(A14,'Base empleados 2025'!A:H,8,0)) | L14: =IF(A14="","",VLOOKUP(A14,'Base empleados 2025'!A:I,9,0))
B15: =+IF(C15="","",B14+1) | C15: =IF(A15="","",IF(ISERROR(VLOOKUP(A15,'Base empleados 2025'!$A:$F,6,FALSE)),VLOOKUP(A15,'Base empleados 2025'!$B:$F,5,FALSE),VLOOKUP(A15,'Base empleados 2025'!$A:$F,6,FALSE))) | D15: =IF(A15="","",IF(ISERROR(VLOOKUP(A15,'Base empleados 2025'!$A:$F,3,FALSE)),VLOOKUP(A15,'Base empleados 2025'!$B:$F,2,FALSE),VLOOKUP(A15,'Base empleados 2025'!$A:$F,3,FALSE))) | E15: =IF(A15="","",IF(ISERROR(VLOOKUP(A15,'Base empleados 2025'!$A:$F,4,FALSE)),VLOOKUP(A15,'Base empleados 2025'!$B:$F,3,FALSE),VLOOKUP(A15,'Base empleados 2025'!$A:$F,4,FALSE))) | F15: =IF(A15="","",IF(ISERROR(VLOOKUP(A15,'Base empleados 2025'!$A:$F,5,FALSE)),VLOOKUP(A15,'Base empleados 2025'!$B:$F,4,FALSE),VLOOKUP(A15,'Base empleados 2025'!$A:$F,5,FALSE))) | G15: =IF(D15="","",VLOOKUP(D15,'Base empleados 2025'!C:G,5,FALSE)) | H15: =IF(ISERROR(VLOOKUP(E15,$E$4:F14,2,FALSE)),"","REPETIDO") -> REPETIDO | J15: =IF(E15="","",VLOOKUP(E15,'Base empleados 2025'!B:G,6,FALSE)) | K15: =IF(A15="","",VLOOKUP(A15,'Base empleados 2025'!A:H,8,0)) | L15: =IF(A15="","",VLOOKUP(A15,'Base empleados 2025'!A:I,9,0))
B16: =+IF(C16="","",B15+1) | C16: =IF(A16="","",IF(ISERROR(VLOOKUP(A16,'Base empleados 2025'!$A:$F,6,FALSE)),VLOOKUP(A16,'Base empleados 2025'!$B:$F,5,FALSE),VLOOKUP(A16,'Base empleados 2025'!$A:$F,6,FALSE))) | D16: =IF(A16="","",IF(ISERROR(VLOOKUP(A16,'Base empleados 2025'!$A:$F,3,FALSE)),VLOOKUP(A16,'Base empleados 2025'!$B:$F,2,FALSE),VLOOKUP(A16,'Base empleados 2025'!$A:$F,3,FALSE))) | E16: =IF(A16="","",IF(ISERROR(VLOOKUP(A16,'Base empleados 2025'!$A:$F,4,FALSE)),VLOOKUP(A16,'Base empleados 2025'!$B:$F,3,FALSE),VLOOKUP(A16,'Base empleados 2025'!$A:$F,4,FALSE))) | F16: =IF(A16="","",IF(ISERROR(VLOOKUP(A16,'Base empleados 2025'!$A:$F,5,FALSE)),VLOOKUP(A16,'Base empleados 2025'!$B:$F,4,FALSE),VLOOKUP(A16,'Base empleados 2025'!$A:$F,5,FALSE))) | G16: =IF(D16="","",VLOOKUP(D16,'Base empleados 2025'!C:G,5,FALSE)) | H16: =IF(ISERROR(VLOOKUP(E16,$E$4:F15,2,FALSE)),"","REPETIDO") -> REPETIDO | J16: =IF(E16="","",VLOOKUP(E16,'Base empleados 2025'!B:G,6,FALSE)) | K16: =IF(A16="","",VLOOKUP(A16,'Base empleados 2025'!A:H,8,0)) | L16: =IF(A16="","",VLOOKUP(A16,'Base empleados 2025'!A:I,9,0))
B17: =+IF(C17="","",B16+1) | C17: =IF(A17="","",IF(ISERROR(VLOOKUP(A17,'Base empleados 2025'!$A:$F,6,FALSE)),VLOOKUP(A17,'Base empleados 2025'!$B:$F,5,FALSE),VLOOKUP(A17,'Base empleados 2025'!$A:$F,6,FALSE))) | D17: =IF(A17="","",IF(ISERROR(VLOOKUP(A17,'Base empleados 2025'!$A:$F,3,FALSE)),VLOOKUP(A17,'Base empleados 2025'!$B:$F,2,FALSE),VLOOKUP(A17,'Base empleados 2025'!$A:$F,3,FALSE))) | E17: =IF(A17="","",IF(ISERROR(VLOOKUP(A17,'Base empleados 2025'!$A:$F,4,FALSE)),VLOOKUP(A17,'Base empleados 2025'!$B:$F,3,FALSE),VLOOKUP(A17,'Base empleados 2025'!$A:$F,4,FALSE))) | F17: =IF(A17="","",IF(ISERROR(VLOOKUP(A17,'Base empleados 2025'!$A:$F,5,FALSE)),VLOOKUP(A17,'Base empleados 2025'!$B:$F,4,FALSE),VLOOKUP(A17,'Base empleados 2025'!$A:$F,5,FALSE))) | G17: =IF(D17="","",VLOOKUP(D17,'Base empleados 2025'!C:G,5,FALSE)) | H17: =IF(ISERROR(VLOOKUP(E17,$E$4:F16,2,FALSE)),"","REPETIDO") -> REPETIDO | J17: =IF(E17="","",VLOOKUP(E17,'Base empleados 2025'!B:G,6,FALSE)) | K17: =IF(A17="","",VLOOKUP(A17,'Base empleados 2025'!A:H,8,0)) | L17: =IF(A17="","",VLOOKUP(A17,'Base empleados 2025'!A:I,9,0))
... B62: =+IF(C62="","",B61+1) | C62: =IF(A62="","",IF(ISERROR(VLOOKUP(A62,'Base empleados 2025'!$A:$F,6,FALSE)),VLOOKUP(A62,'Base empleados 2025'!$B:$F,5,FALSE),VLOOKUP(A62,'Base empleados 2025'!$A:$F,6,FALSE))) | D62: =IF(A62="","",IF(ISERROR(VLOOKUP(A62,'Base empleados 2025'!$A:$F,3,FALSE)),VLOOKUP(A62,'Base empleados 2025'!$B:$F,2,FALSE),VLOOKUP(A62,'Base empleados 2025'!$A:$F,3,FALSE))) | E62: =IF(A62="","",IF(ISERROR(VLOOKUP(A62,'Base empleados 2025'!$A:$F,4,FALSE)),VLOOKUP(A62,'Base empleados 2025'!$B:$F,3,FALSE),VLOOKUP(A62,'Base empleados 2025'!$A:$F,4,FALSE))) | F62: =IF(A62="","",IF(ISERROR(VLOOKUP(A62,'Base empleados 2025'!$A:$F,5,FALSE)),VLOOKUP(A62,'Base empleados 2025'!$B:$F,4,FALSE),VLOOKUP(A62,'Base empleados 2025'!$A:$F,5,FALSE))) | G62: =IF(D62="","",VLOOKUP(D62,'Base empleados 2025'!C:G,5,FALSE)) | H62: =IF(ISERROR(VLOOKUP(E62,$E$4:F61,2,FALSE)),"","REPETIDO") -> REPETIDO | J62: =IF(E62="","",VLOOKUP(E62,'Base empleados 2025'!B:G,6,FALSE)) | K62: =IF(A62="","",VLOOKUP(A62,'Base empleados 2025'!A:H,8,0)) | L62: =IF(A62="","",VLOOKUP(A62,'Base empleados 2025'!A:I,9,0))
B63: =+IF(C63="","",B62+1) | C63: =IF(A63="","",IF(ISERROR(VLOOKUP(A63,'Base empleados 2025'!$A:$F,6,FALSE)),VLOOKUP(A63,'Base empleados 2025'!$B:$F,5,FALSE),VLOOKUP(A63,'Base empleados 2025'!$A:$F,6,FALSE))) | D63: =IF(A63="","",IF(ISERROR(VLOOKUP(A63,'Base empleados 2025'!$A:$F,3,FALSE)),VLOOKUP(A63,'Base empleados 2025'!$B:$F,2,FALSE),VLOOKUP(A63,'Base empleados 2025'!$A:$F,3,FALSE))) | E63: =IF(A63="","",IF(ISERROR(VLOOKUP(A63,'Base empleados 2025'!$A:$F,4,FALSE)),VLOOKUP(A63,'Base empleados 2025'!$B:$F,3,FALSE),VLOOKUP(A63,'Base empleados 2025'!$A:$F,4,FALSE))) | F63: =IF(A63="","",IF(ISERROR(VLOOKUP(A63,'Base empleados 2025'!$A:$F,5,FALSE)),VLOOKUP(A63,'Base empleados 2025'!$B:$F,4,FALSE),VLOOKUP(A63,'Base empleados 2025'!$A:$F,5,FALSE))) | G63: =IF(D63="","",VLOOKUP(D63,'Base empleados 2025'!C:G,5,FALSE)) | H63: =IF(ISERROR(VLOOKUP(E63,$E$4:F62,2,FALSE)),"","REPETIDO") -> REPETIDO | J63: =IF(E63="","",VLOOKUP(E63,'Base empleados 2025'!B:G,6,FALSE)) | K63: =IF(A63="","",VLOOKUP(A63,'Base empleados 2025'!A:H,8,0)) | L63: =IF(A63="","",VLOOKUP(A63,'Base empleados 2025'!A:I,9,0)) | M63: 105465 | N63: 106132 | O63: 107035 | P63: 109348 | Q63: 107458 | R63: 106853 | S63: 110111 | T63: 94493 | U63: 111062 | V63: 93869 | W63: 93758 | X63: 94886 | Y63: 109370 | Z63: 108955 | AA63: 93656 | AB63: 94283 | AC63: 107048 | AE63: 110813 | AF63: 111027 | AG63: 94494 | AH63: 93434 | AI63: 111300 | AJ63: 110471 | AK63: 106919 | AL63: 111164 | AM63: 110719 | AN63: 94933 | AO63: 108406 | AP63: 109961 | AQ63: 106286 | AR63: 111332 | AS63: 110406 | AT63: 93504 | AU63: 111061 | AV63: 106860 | AW63: 110906 | AX63: 110778 | AY63: 94765 | AZ63: 110743 | BA63: 95212 | BB63: 94553 | BC63: 109262 | BD63: 108130 | BE63: 105914 | BF63: 93392 | BG63: 107040 | BH63: 94584 | BI63: 105467 | BJ63: 108196 | BK63: 94362 | BL63: 107354 | BM63: 110895 | BN63: 111045 | BO63: 110901 | BP63: 94905 | BQ63: 109619 | BR63: 94534 | BS63: 109888 | BT63: 94559 | BU63: 111226 | BV63: 111208 | BW63: 94506 | BX63: 111089
B64: =+IF(C64="","",B63+1) | C64: =IF(A64="","",IF(ISERROR(VLOOKUP(A64,'Base empleados 2025'!$A:$F,6,FALSE)),VLOOKUP(A64,'Base empleados 2025'!$B:$F,5,FALSE),VLOOKUP(A64,'Base empleados 2025'!$A:$F,6,FALSE))) | D64: =IF(A64="","",IF(ISERROR(VLOOKUP(A64,'Base empleados 2025'!$A:$F,3,FALSE)),VLOOKUP(A64,'Base empleados 2025'!$B:$F,2,FALSE),VLOOKUP(A64,'Base empleados 2025'!$A:$F,3,FALSE))) | E64: =IF(A64="","",IF(ISERROR(VLOOKUP(A64,'Base empleados 2025'!$A:$F,4,FALSE)),VLOOKUP(A64,'Base empleados 2025'!$B:$F,3,FALSE),VLOOKUP(A64,'Base empleados 2025'!$A:$F,4,FALSE))) | F64: =IF(A64="","",IF(ISERROR(VLOOKUP(A64,'Base empleados 2025'!$A:$F,5,FALSE)),VLOOKUP(A64,'Base empleados 2025'!$B:$F,4,FALSE),VLOOKUP(A64,'Base empleados 2025'!$A:$F,5,FALSE))) | G64: =IF(D64="","",VLOOKUP(D64,'Base empleados 2025'!C:G,5,FALSE)) | H64: =IF(ISERROR(VLOOKUP(E64,$E$4:F63,2,FALSE)),"","REPETIDO") -> REPETIDO | J64: =IF(E64="","",VLOOKUP(E64,'Base empleados 2025'!B:G,6,FALSE)) | K64: =IF(A64="","",VLOOKUP(A64,'Base empleados 2025'!A:H,8,0)) | L64: =IF(A64="","",VLOOKUP(A64,'Base empleados 2025'!A:I,9,0))
B65: =+IF(C65="","",B64+1) | C65: =IF(A65="","",IF(ISERROR(VLOOKUP(A65,'Base empleados 2025'!$A:$F,6,FALSE)),VLOOKUP(A65,'Base empleados 2025'!$B:$F,5,FALSE),VLOOKUP(A65,'Base empleados 2025'!$A:$F,6,FALSE))) | D65: =IF(A65="","",IF(ISERROR(VLOOKUP(A65,'Base empleados 2025'!$A:$F,3,FALSE)),VLOOKUP(A65,'Base empleados 2025'!$B:$F,2,FALSE),VLOOKUP(A65,'Base empleados 2025'!$A:$F,3,FALSE))) | E65: =IF(A65="","",IF(ISERROR(VLOOKUP(A65,'Base empleados 2025'!$A:$F,4,FALSE)),VLOOKUP(A65,'Base empleados 2025'!$B:$F,3,FALSE),VLOOKUP(A65,'Base empleados 2025'!$A:$F,4,FALSE))) | F65: =IF(A65="","",IF(ISERROR(VLOOKUP(A65,'Base empleados 2025'!$A:$F,5,FALSE)),VLOOKUP(A65,'Base empleados 2025'!$B:$F,4,FALSE),VLOOKUP(A65,'Base empleados 2025'!$A:$F,5,FALSE))) | G65: =IF(D65="","",VLOOKUP(D65,'Base empleados 2025'!C:G,5,FALSE)) | H65: =IF(ISERROR(VLOOKUP(E65,$E$4:F64,2,FALSE)),"","REPETIDO") -> REPETIDO | J65: =IF(E65="","",VLOOKUP(E65,'Base empleados 2025'!B:G,6,FALSE)) | K65: =IF(A65="","",VLOOKUP(A65,'Base empleados 2025'!A:H,8,0)) | L65: =IF(A65="","",VLOOKUP(A65,'Base empleados 2025'!A:I,9,0))
B66: =+IF(C66="","",B65+1) | C66: =IF(A66="","",IF(ISERROR(VLOOKUP(A66,'Base empleados 2025'!$A:$F,6,FALSE)),VLOOKUP(A66,'Base empleados 2025'!$B:$F,5,FALSE),VLOOKUP(A66,'Base empleados 2025'!$A:$F,6,FALSE))) | D66: =IF(A66="","",IF(ISERROR(VLOOKUP(A66,'Base empleados 2025'!$A:$F,3,FALSE)),VLOOKUP(A66,'Base empleados 2025'!$B:$F,2,FALSE),VLOOKUP(A66,'Base empleados 2025'!$A:$F,3,FALSE))) | E66: =IF(A66="","",IF(ISERROR(VLOOKUP(A66,'Base empleados 2025'!$A:$F,4,FALSE)),VLOOKUP(A66,'Base empleados 2025'!$B:$F,3,FALSE),VLOOKUP(A66,'Base empleados 2025'!$A:$F,4,FALSE))) | F66: =IF(A66="","",IF(ISERROR(VLOOKUP(A66,'Base empleados 2025'!$A:$F,5,FALSE)),VLOOKUP(A66,'Base empleados 2025'!$B:$F,4,FALSE),VLOOKUP(A66,'Base empleados 2025'!$A:$F,5,FALSE))) | G66: =IF(D66="","",VLOOKUP(D66,'Base empleados 2025'!C:G,5,FALSE)) | H66: =IF(ISERROR(VLOOKUP(E66,$E$4:F65,2,FALSE)),"","REPETIDO") -> REPETIDO | J66: =IF(E66="","",VLOOKUP(E66,'Base empleados 2025'!B:G,6,FALSE)) | K66: =IF(A66="","",VLOOKUP(A66,'Base empleados 2025'!A:H,8,0)) | L66: =IF(A66="","",VLOOKUP(A66,'Base empleados 2025'!A:I,9,0))
B67: =+IF(C67="","",B66+1) | C67: =IF(A67="","",IF(ISERROR(VLOOKUP(A67,'Base empleados 2025'!$A:$F,6,FALSE)),VLOOKUP(A67,'Base empleados 2025'!$B:$F,5,FALSE),VLOOKUP(A67,'Base empleados 2025'!$A:$F,6,FALSE))) | D67: =IF(A67="","",IF(ISERROR(VLOOKUP(A67,'Base empleados 2025'!$A:$F,3,FALSE)),VLOOKUP(A67,'Base empleados 2025'!$B:$F,2,FALSE),VLOOKUP(A67,'Base empleados 2025'!$A:$F,3,FALSE))) | E67: =IF(A67="","",IF(ISERROR(VLOOKUP(A67,'Base empleados 2025'!$A:$F,4,FALSE)),VLOOKUP(A67,'Base empleados 2025'!$B:$F,3,FALSE),VLOOKUP(A67,'Base empleados 2025'!$A:$F,4,FALSE))) | F67: =IF(A67="","",IF(ISERROR(VLOOKUP(A67,'Base empleados 2025'!$A:$F,5,FALSE)),VLOOKUP(A67,'Base empleados 2025'!$B:$F,4,FALSE),VLOOKUP(A67,'Base empleados 2025'!$A:$F,5,FALSE))) | G67: =IF(D67="","",VLOOKUP(D67,'Base empleados 2025'!C:G,5,FALSE)) | H67: =IF(ISERROR(VLOOKUP(E67,$E$4:F66,2,FALSE)),"","REPETIDO") -> REPETIDO | J67: =IF(E67="","",VLOOKUP(E67,'Base empleados 2025'!B:G,6,FALSE)) | K67: =IF(A67="","",VLOOKUP(A67,'Base empleados 2025'!A:H,8,0)) | L67: =IF(A67="","",VLOOKUP(A67,'Base empleados 2025'!A:I,9,0))
B68: =+IF(C68="","",B67+1) | C68: =IF(A68="","",IF(ISERROR(VLOOKUP(A68,'Base empleados 2025'!$A:$F,6,FALSE)),VLOOKUP(A68,'Base empleados 2025'!$B:$F,5,FALSE),VLOOKUP(A68,'Base empleados 2025'!$A:$F,6,FALSE))) | D68: =IF(A68="","",IF(ISERROR(VLOOKUP(A68,'Base empleados 2025'!$A:$F,3,FALSE)),VLOOKUP(A68,'Base empleados 2025'!$B:$F,2,FALSE),VLOOKUP(A68,'Base empleados 2025'!$A:$F,3,FALSE))) | E68: =IF(A68="","",IF(ISERROR(VLOOKUP(A68,'Base empleados 2025'!$A:$F,4,FALSE)),VLOOKUP(A68,'Base empleados 2025'!$B:$F,3,FALSE),VLOOKUP(A68,'Base empleados 2025'!$A:$F,4,FALSE))) | F68: =IF(A68="","",IF(ISERROR(VLOOKUP(A68,'Base empleados 2025'!$A:$F,5,FALSE)),VLOOKUP(A68,'Base empleados 2025'!$B:$F,4,FALSE),VLOOKUP(A68,'Base empleados 2025'!$A:$F,5,FALSE))) | G68: =IF(D68="","",VLOOKUP(D68,'Base empleados 2025'!C:G,5,FALSE)) | H68: =IF(ISERROR(VLOOKUP(E68,$E$4:F67,2,FALSE)),"","REPETIDO") -> REPETIDO | J68: =IF(E68="","",VLOOKUP(E68,'Base empleados 2025'!B:G,6,FALSE)) | K68: =IF(A68="","",VLOOKUP(A68,'Base empleados 2025'!A:H,8,0)) | L68: =IF(A68="","",VLOOKUP(A68,'Base empleados 2025'!A:I,9,0))
B69: =+IF(C69="","",B68+1) | C69: =IF(A69="","",IF(ISERROR(VLOOKUP(A69,'Base empleados 2025'!$A:$F,6,FALSE)),VLOOKUP(A69,'Base empleados 2025'!$B:$F,5,FALSE),VLOOKUP(A69,'Base empleados 2025'!$A:$F,6,FALSE))) | D69: =IF(A69="","",IF(ISERROR(VLOOKUP(A69,'Base empleados 2025'!$A:$F,3,FALSE)),VLOOKUP(A69,'Base empleados 2025'!$B:$F,2,FALSE),VLOOKUP(A69,'Base empleados 2025'!$A:$F,3,FALSE))) | E69: =IF(A69="","",IF(ISERROR(VLOOKUP(A69,'Base empleados 2025'!$A:$F,4,FALSE)),VLOOKUP(A69,'Base empleados 2025'!$B:$F,3,FALSE),VLOOKUP(A69,'Base empleados 2025'!$A:$F,4,FALSE))) | F69: =IF(A69="","",IF(ISERROR(VLOOKUP(A69,'Base empleados 2025'!$A:$F,5,FALSE)),VLOOKUP(A69,'Base empleados 2025'!$B:$F,4,FALSE),VLOOKUP(A69,'Base empleados 2025'!$A:$F,5,FALSE))) | G69: =IF(D69="","",VLOOKUP(D69,'Base empleados 2025'!C:G,5,FALSE)) | H69: =IF(ISERROR(VLOOKUP(E69,$E$4:F68,2,FALSE)),"","REPETIDO") -> REPETIDO | J69: =IF(E69="","",VLOOKUP(E69,'Base empleados 2025'!B:G,6,FALSE)) | K69: =IF(A69="","",VLOOKUP(A69,'Base empleados 2025'!A:H,8,0)) | L69: =IF(A69="","",VLOOKUP(A69,'Base empleados 2025'!A:I,9,0))
B70: =+IF(C70="","",B69+1) | C70: =IF(A70="","",IF(ISERROR(VLOOKUP(A70,'Base empleados 2025'!$A:$F,6,FALSE)),VLOOKUP(A70,'Base empleados 2025'!$B:$F,5,FALSE),VLOOKUP(A70,'Base empleados 2025'!$A:$F,6,FALSE))) | D70: =IF(A70="","",IF(ISERROR(VLOOKUP(A70,'Base empleados 2025'!$A:$F,3,FALSE)),VLOOKUP(A70,'Base empleados 2025'!$B:$F,2,FALSE),VLOOKUP(A70,'Base empleados 2025'!$A:$F,3,FALSE))) | E70: =IF(A70="","",IF(ISERROR(VLOOKUP(A70,'Base empleados 2025'!$A:$F,4,FALSE)),VLOOKUP(A70,'Base empleados 2025'!$B:$F,3,FALSE),VLOOKUP(A70,'Base empleados 2025'!$A:$F,4,FALSE))) | F70: =IF(A70="","",IF(ISERROR(VLOOKUP(A70,'Base empleados 2025'!$A:$F,5,FALSE)),VLOOKUP(A70,'Base empleados 2025'!$B:$F,4,FALSE),VLOOKUP(A70,'Base empleados 2025'!$A:$F,5,FALSE))) | G70: =IF(D70="","",VLOOKUP(D70,'Base empleados 2025'!C:G,5,FALSE)) | H70: =IF(ISERROR(VLOOKUP(E70,$E$4:F69,2,FALSE)),"","REPETIDO") -> REPETIDO | J70: =IF(E70="","",VLOOKUP(E70,'Base empleados 2025'!B:G,6,FALSE)) | K70: =IF(A70="","",VLOOKUP(A70,'Base empleados 2025'!A:H,8,0)) | L70: =IF(A70="","",VLOOKUP(A70,'Base empleados 2025'!A:I,9,0))
B71: =+IF(C71="","",B70+1) | C71: =IF(A71="","",IF(ISERROR(VLOOKUP(A71,'Base empleados 2025'!$A:$F,6,FALSE)),VLOOKUP(A71,'Base empleados 2025'!$B:$F,5,FALSE),VLOOKUP(A71,'Base empleados 2025'!$A:$F,6,FALSE))) | D71: =IF(A71="","",IF(ISERROR(VLOOKUP(A71,'Base empleados 2025'!$A:$F,3,FALSE)),VLOOKUP(A71,'Base empleados 2025'!$B:$F,2,FALSE),VLOOKUP(A71,'Base empleados 2025'!$A:$F,3,FALSE))) | E71: =IF(A71="","",IF(ISERROR(VLOOKUP(A71,'Base empleados 2025'!$A:$F,4,FALSE)),VLOOKUP(A71,'Base empleados 2025'!$B:$F,3,FALSE),VLOOKUP(A71,'Base empleados 2025'!$A:$F,4,FALSE))) | F71: =IF(A71="","",IF(ISERROR(VLOOKUP(A71,'Base empleados 2025'!$A:$F,5,FALSE)),VLOOKUP(A71,'Base empleados 2025'!$B:$F,4,FALSE),VLOOKUP(A71,'Base empleados 2025'!$A:$F,5,FALSE))) | G71: =IF(D71="","",VLOOKUP(D71,'Base empleados 2025'!C:G,5,FALSE)) | H71: =IF(ISERROR(VLOOKUP(E71,$E$4:F70,2,FALSE)),"","REPETIDO") -> REPETIDO | J71: =IF(E71="","",VLOOKUP(E71,'Base empleados 2025'!B:G,6,FALSE)) | K71: =IF(A71="","",VLOOKUP(A71,'Base empleados 2025'!A:H,8,0)) | L71: =IF(A71="","",VLOOKUP(A71,'Base empleados 2025'!A:I,9,0))
B72: =+IF(C72="","",B71+1) | C72: =IF(A72="","",IF(ISERROR(VLOOKUP(A72,'Base empleados 2025'!$A:$F,6,FALSE)),VLOOKUP(A72,'Base empleados 2025'!$B:$F,5,FALSE),VLOOKUP(A72,'Base empleados 2025'!$A:$F,6,FALSE))) | D72: =IF(A72="","",IF(ISERROR(VLOOKUP(A72,'Base empleados 2025'!$A:$F,3,FALSE)),VLOOKUP(A72,'Base empleados 2025'!$B:$F,2,FALSE),VLOOKUP(A72,'Base empleados 2025'!$A:$F,3,FALSE))) | E72: =IF(A72="","",IF(ISERROR(VLOOKUP(A72,'Base empleados 2025'!$A:$F,4,FALSE)),VLOOKUP(A72,'Base empleados 2025'!$B:$F,3,FALSE),VLOOKUP(A72,'Base empleados 2025'!$A:$F,4,FALSE))) | F72: =IF(A72="","",IF(ISERROR(VLOOKUP(A72,'Base empleados 2025'!$A:$F,5,FALSE)),VLOOKUP(A72,'Base empleados 2025'!$B:$F,4,FALSE),VLOOKUP(A72,'Base empleados 2025'!$A:$F,5,FALSE))) | G72: =IF(D72="","",VLOOKUP(D72,'Base empleados 2025'!C:G,5,FALSE)) | H72: =IF(ISERROR(VLOOKUP(E72,$E$4:F71,2,FALSE)),"","REPETIDO") -> REPETIDO | J72: =IF(E72="","",VLOOKUP(E72,'Base empleados 2025'!B:G,6,FALSE)) | K72: =IF(A72="","",VLOOKUP(A72,'Base empleados 2025'!A:H,8,0)) | L72: =IF(A72="","",VLOOKUP(A72,'Base empleados 2025'!A:I,9,0))
B73: =+IF(C73="","",B72+1) | C73: =IF(A73="","",IF(ISERROR(VLOOKUP(A73,'Base empleados 2025'!$A:$F,6,FALSE)),VLOOKUP(A73,'Base empleados 2025'!$B:$F,5,FALSE),VLOOKUP(A73,'Base empleados 2025'!$A:$F,6,FALSE))) | D73: =IF(A73="","",IF(ISERROR(VLOOKUP(A73,'Base empleados 2025'!$A:$F,3,FALSE)),VLOOKUP(A73,'Base empleados 2025'!$B:$F,2,FALSE),VLOOKUP(A73,'Base empleados 2025'!$A:$F,3,FALSE))) | E73: =IF(A73="","",IF(ISERROR(VLOOKUP(A73,'Base empleados 2025'!$A:$F,4,FALSE)),VLOOKUP(A73,'Base empleados 2025'!$B:$F,3,FALSE),VLOOKUP(A73,'Base empleados 2025'!$A:$F,4,FALSE))) | F73: =IF(A73="","",IF(ISERROR(VLOOKUP(A73,'Base empleados 2025'!$A:$F,5,FALSE)),VLOOKUP(A73,'Base empleados 2025'!$B:$F,4,FALSE),VLOOKUP(A73,'Base empleados 2025'!$A:$F,5,FALSE))) | G73: =IF(D73="","",VLOOKUP(D73,'Base empleados 2025'!C:G,5,FALSE)) | H73: =IF(ISERROR(VLOOKUP(E73,$E$4:F72,2,FALSE)),"","REPETIDO") -> REPETIDO | J73: =IF(E73="","",VLOOKUP(E73,'Base empleados 2025'!B:G,6,FALSE)) | K73: =IF(A73="","",VLOOKUP(A73,'Base empleados 2025'!A:H,8,0)) | L73: =IF(A73="","",VLOOKUP(A73,'Base empleados 2025'!A:I,9,0))
B74: =+IF(C74="","",B73+1) | C74: =IF(A74="","",IF(ISERROR(VLOOKUP(A74,'Base empleados 2025'!$A:$F,6,FALSE)),VLOOKUP(A74,'Base empleados 2025'!$B:$F,5,FALSE),VLOOKUP(A74,'Base empleados 2025'!$A:$F,6,FALSE))) | D74: =IF(A74="","",IF(ISERROR(VLOOKUP(A74,'Base empleados 2025'!$A:$F,3,FALSE)),VLOOKUP(A74,'Base empleados 2025'!$B:$F,2,FALSE),VLOOKUP(A74,'Base empleados 2025'!$A:$F,3,FALSE))) | E74: =IF(A74="","",IF(ISERROR(VLOOKUP(A74,'Base empleados 2025'!$A:$F,4,FALSE)),VLOOKUP(A74,'Base empleados 2025'!$B:$F,3,FALSE),VLOOKUP(A74,'Base empleados 2025'!$A:$F,4,FALSE))) | F74: =IF(A74="","",IF(ISERROR(VLOOKUP(A74,'Base empleados 2025'!$A:$F,5,FALSE)),VLOOKUP(A74,'Base empleados 2025'!$B:$F,4,FALSE),VLOOKUP(A74,'Base empleados 2025'!$A:$F,5,FALSE))) | G74: =IF(D74="","",VLOOKUP(D74,'Base empleados 2025'!C:G,5,FALSE)) | H74: =IF(ISERROR(VLOOKUP(E74,$E$4:F73,2,FALSE)),"","REPETIDO") -> REPETIDO | J74: =IF(E74="","",VLOOKUP(E74,'Base empleados 2025'!B:G,6,FALSE)) | K74: =IF(A74="","",VLOOKUP(A74,'Base empleados 2025'!A:H,8,0)) | L74: =IF(A74="","",VLOOKUP(A74,'Base empleados 2025'!A:I,9,0))
B75: =+IF(C75="","",B74+1) | C75: =IF(A75="","",IF(ISERROR(VLOOKUP(A75,'Base empleados 2025'!$A:$F,6,FALSE)),VLOOKUP(A75,'Base empleados 2025'!$B:$F,5,FALSE),VLOOKUP(A75,'Base empleados 2025'!$A:$F,6,FALSE))) | D75: =IF(A75="","",IF(ISERROR(VLOOKUP(A75,'Base empleados 2025'!$A:$F,3,FALSE)),VLOOKUP(A75,'Base empleados 2025'!$B:$F,2,FALSE),VLOOKUP(A75,'Base empleados 2025'!$A:$F,3,FALSE))) | E75: =IF(A75="","",IF(ISERROR(VLOOKUP(A75,'Base empleados 2025'!$A:$F,4,FALSE)),VLOOKUP(A75,'Base empleados 2025'!$B:$F,3,FALSE),VLOOKUP(A75,'Base empleados 2025'!$A:$F,4,FALSE))) | F75: =IF(A75="","",IF(ISERROR(VLOOKUP(A75,'Base empleados 2025'!$A:$F,5,FALSE)),VLOOKUP(A75,'Base empleados 2025'!$B:$F,4,FALSE),VLOOKUP(A75,'Base empleados 2025'!$A:$F,5,FALSE))) | G75: =IF(D75="","",VLOOKUP(D75,'Base empleados 2025'!C:G,5,FALSE)) | H75: =IF(ISERROR(VLOOKUP(E75,$E$4:F74,2,FALSE)),"","REPETIDO") -> REPETIDO | J75: =IF(E75="","",VLOOKUP(E75,'Base empleados 2025'!B:G,6,FALSE)) | K75: =IF(A75="","",VLOOKUP(A75,'Base empleados 2025'!A:H,8,0)) | L75: =IF(A75="","",VLOOKUP(A75,'Base empleados 2025'!A:I,9,0))
... B3491: =+IF(C3491="","",B3490+1) | C3491: =IF(A3491="","",IF(ISERROR(VLOOKUP(A3491,'Base empleados 2025'!$A:$F,6,FALSE)),VLOOKUP(A3491,'Base empleados 2025'!$B:$F,5,FALSE),VLOOKUP(A3491,'Base empleados 2025'!$A:$F,6,FALSE))) | D3491: =IF(A3491="","",IF(ISERROR(VLOOKUP(A3491,'Base empleados 2025'!$A:$F,3,FALSE)),VLOOKUP(A3491,'Base empleados 2025'!$B:$F,2,FALSE),VLOOKUP(A3491,'Base empleados 2025'!$A:$F,3,FALSE))) | E3491: =IF(A3491="","",IF(ISERROR(VLOOKUP(A3491,'Base empleados 2025'!$A:$F,4,FALSE)),VLOOKUP(A3491,'Base empleados 2025'!$B:$F,3,FALSE),VLOOKUP(A3491,'Base empleados 2025'!$A:$F,4,FALSE))) | F3491: =IF(A3491="","",IF(ISERROR(VLOOKUP(A3491,'Base empleados 2025'!$A:$F,5,FALSE)),VLOOKUP(A3491,'Base empleados 2025'!$B:$F,4,FALSE),VLOOKUP(A3491,'Base empleados 2025'!$A:$F,5,FALSE))) | G3491: =IF(D3491="","",VLOOKUP(D3491,'Base empleados 2025'!C:G,5,FALSE)) | H3491: =IF(ISERROR(VLOOKUP(E3491,$E$4:F3490,2,FALSE)),"","REPETIDO") -> REPETIDO | J3491: =IF(E3491="","",VLOOKUP(E3491,'Base empleados 2025'!B:G,6,FALSE)) | K3491: =IF(A3491="","",VLOOKUP(A3491,'Base empleados 2025'!A:H,8,0)) | L3491: =IF(A3491="","",VLOOKUP(A3491,'Base empleados 2025'!A:I,9,0))
